Workbook

Sheet README
A2: Golden Manufacturing Ltd v2.48 data pack
A4: Topic | B4: Dataset documentation
A5: Data pack | B5: Golden Manufacturing Ltd v2.48. Synthetic accounting and operational records for a UK manufacturer with 32 employees and a December year-end.
A6: Periods and units | B6: The pack contains monthly records for calendar FY2025 and FY2026. Monetary values are GBP in whole pounds; unit prices are GBP per unit. Dates are numeric Excel dates.
A7: Management accounts | B7: Management PL contains the canonical monthly P&L. Contribution 0 is the source-defined revenue less costs-before-C0 measure. Payroll, other overhead, depreciation, interest and tax are shown separately.
A8: Balance sheet | B8: Balance Sheet contains month-end accounting stocks. Net trade working capital is trade receivables plus inventory less trade payables. Accounting balance checks compare total assets with liabilities and equity.
A9: Customer/product records | B9: Customer Product contains a selected customer/product population. Its key is period + customer ID + product. A/B quantities are comparable sold units within each SKU. Blank quantity/price fields are unavailable measurements.
A10: Sources and versions | B10: Source IDs and Context IDs link records to the Context registry. Versions identifies revenue release history, canonical status, superseding record and reason. Its key is entity + period + metric + version.
A11: Version treatment | B11: Management PL already contains canonical revenue. Versions is an alternative history of the same revenue, not additional transactions to append. Release dates are scenario metadata.
A12: Cash and production | B12: Cash and Output contains asset additions, dividends, cash-classification fields and available production counts. Asset additions do not establish payment timing. Production counts measure completed good units, not sales.
A13: Missing values | B13: Blank values mean no measurement supplied, not zero. UNCLASSIFIED is the recorded cash classification status. Retain measurement, population, time and accounting basis when using these fields.
A14: Accounting construction | B14: Synthetic opening Dec24 retained earnings are 2,000,000, capital 1,000,000 and borrowings 2,000,000. Retained earnings roll with profit after tax less monthly dividends. Opening net fixed assets are 2,000,000.
A15: Cash construction | B15: Cash is an accounting stock calculated from liabilities/equity less noncash assets. Fixed assets roll with additions less depreciation. Noncash adjustments and transaction-level cash classifications are not supplied.
A16: Joins and record grain | B16: PL, BS and cash records use one row per month. Customer/product data uses one row per monthly customer/product combination. Flow measurements and month-end stocks have different aggregation rules.

Sheet Management PL
A2: Monthly management P&L (GBP)
A4: Period | B4: FY | C4: Revenue | D4: Contribution 0 | E4: C0 margin | F4: Costs before C0 | G4: Payroll after C0 | H4: Other overhead | I4: Depreciation | J4: Operating profit | K4: Interest expense | L4: Profit before tax | M4: Tax expense | N4: Profit after tax | O4: Source ID | P4: Version | Q4: Context ID
A5: 45658 | B5: 2025 | C5: 900000 | D5: 271800 | E5: =D5/C5 -> 0.302 | F5: =C5-D5 -> 628200 | G5: 125000 | H5: 65000 | I5: 20000 | J5: =D5-SUM(G5:I5) -> 61800 | K5: 10000 | L5: =J5-K5 -> 51800 | M5: =L5*0.25 -> 12950 | N5: =L5-M5 -> 38850 | O5: MA-2025-01 | P5: 1 | Q5: CTX-PL
A6: 45689 | B6: 2025 | C6: 936000 | D6: 281700 | E6: =D6/C6 -> 0.30096154 | F6: =C6-D6 -> 654300 | G6: 125000 | H6: 65000 | I6: 20000 | J6: =D6-SUM(G6:I6) -> 71700 | K6: 10000 | L6: =J6-K6 -> 61700 | M6: =L6*0.25 -> 15425 | N6: =L6-M6 -> 46275 | O6: MA-2025-02 | P6: 1 | Q6: CTX-PL
A7: 45717 | B7: 2025 | C7: 972000 | D7: 291600 | E7: =D7/C7 -> 0.3 | F7: =C7-D7 -> 680400 | G7: 125000 | H7: 65000 | I7: 20000 | J7: =D7-SUM(G7:I7) -> 81600 | K7: 10000 | L7: =J7-K7 -> 71600 | M7: =L7*0.25 -> 17900 | N7: =L7-M7 -> 53700 | O7: MA-2025-03 | P7: 1 | Q7: CTX-PL
A8: 45748 | B8: 2025 | C8: 948000 | D8: 283500 | E8: =D8/C8 -> 0.29905063 | F8: =C8-D8 -> 664500 | G8: 125000 | H8: 65000 | I8: 20000 | J8: =D8-SUM(G8:I8) -> 73500 | K8: 10000 | L8: =J8-K8 -> 63500 | M8: =L8*0.25 -> 15875 | N8: =L8-M8 -> 47625 | O8: MA-2025-04 | P8: 1 | Q8: CTX-PL
A9: 45778 | B9: 2025 | C9: 984000 | D9: 296200 | E9: =D9/C9 -> 0.30101626 | F9: =C9-D9 -> 687800 | G9: 125000 | H9: 65000 | I9: 20000 | J9: =D9-SUM(G9:I9) -> 86200 | K9: 10000 | L9: =J9-K9 -> 76200 | M9: =L9*0.25 -> 19050 | N9: =L9-M9 -> 57150 | O9: MA-2025-05 | P9: 1 | Q9: CTX-PL
A10: 45809 | B10: 2025 | C10: 1008000 | D10: 302400 | E10: =D10/C10 -> 0.3 | F10: =C10-D10 -> 705600 | G10: 125000 | H10: 65000 | I10: 20000 | J10: =D10-SUM(G10:I10) -> 92400 | K10: 10000 | L10: =J10-K10 -> 82400 | M10: =L10*0.25 -> 20600 | N10: =L10-M10 -> 61800 | O10: MA-2025-06 | P10: 1 | Q10: CTX-PL
A11: 45839 | B11: 2025 | C11: 948000 | D11: 282500 | E11: =D11/C11 -> 0.29799578 | F11: =C11-D11 -> 665500 | G11: 125000 | H11: 65000 | I11: 20000 | J11: =D11-SUM(G11:I11) -> 72500 | K11: 10000 | L11: =J11-K11 -> 62500 | M11: =L11*0.25 -> 15625 | N11: =L11-M11 -> 46875 | O11: MA-2025-07 | P11: 1 | Q11: CTX-PL
A12: 45870 | B12: 2025 | C12: 900000 | D12: 267300 | E12: =D12/C12 -> 0.297 | F12: =C12-D12 -> 632700 | G12: 125000 | H12: 65000 | I12: 20000 | J12: =D12-SUM(G12:I12) -> 57300 | K12: 10000 | L12: =J12-K12 -> 47300 | M12: =L12*0.25 -> 11825 | N12: =L12-M12 -> 35475 | O12: MA-2025-08 | P12: 1 | Q12: CTX-PL
A13: 45901 | B13: 2025 | C13: 996000 | D13: 297800 | E13: =D13/C13 -> 0.29899598 | F13: =C13-D13 -> 698200 | G13: 125000 | H13: 65000 | I13: 20000 | J13: =D13-SUM(G13:I13) -> 87800 | K13: 10000 | L13: =J13-K13 -> 77800 | M13: =L13*0.25 -> 19450 | N13: =L13-M13 -> 58350 | O13: MA-2025-09 | P13: 1 | Q13: CTX-PL
A14: 45931 | B14: 2025 | C14: 1056000 | D14: 317900 | E14: =D14/C14 -> 0.30104167 | F14: =C14-D14 -> 738100 | G14: 125000 | H14: 65000 | I14: 20000 | J14: =D14-SUM(G14:I14) -> 107900 | K14: 10000 | L14: =J14-K14 -> 97900 | M14: =L14*0.25 -> 24475 | N14: =L14-M14 -> 73425 | O14: MA-2025-10 | P14: 1 | Q14: CTX-PL
A15: 45962 | B15: 2025 | C15: 1104000 | D15: 333400 | E15: =D15/C15 -> 0.30199275 | F15: =C15-D15 -> 770600 | G15: 125000 | H15: 65000 | I15: 20000 | J15: =D15-SUM(G15:I15) -> 123400 | K15: 10000 | L15: =J15-K15 -> 113400 | M15: =L15*0.25 -> 28350 | N15: =L15-M15 -> 85050 | O15: MA-2025-11 | P15: 1 | Q15: CTX-PL
A16: 45992 | B16: 2025 | C16: 1248000 | D16: 373900 | E16: =D16/C16 -> 0.29959936 | F16: =C16-D16 -> 874100 | G16: 125000 | H16: 65000 | I16: 20000 | J16: =D16-SUM(G16:I16) -> 163900 | K16: 10000 | L16: =J16-K16 -> 153900 | M16: =L16*0.25 -> 38475 | N16: =L16-M16 -> 115425 | O16: MA-2025-12 | P16: 1 | Q16: CTX-PL
... A28: 46357 | B28: 2026 | C28: 1347000 | D28: 374100 | E28: =D28/C28 -> 0.27772829 | F28: =C28-D28 -> 972900 | G28: 140000 | H28: 72000 | I28: 20000 | J28: =D28-SUM(G28:I28) -> 142100 | K28: 10000 | L28: =J28-K28 -> 132100 | M28: =L28*0.25 -> 33025 | N28: =L28-M28 -> 99075 | O28: MA-2026-12 | P28: 1 | Q28: CTX-PL

Sheet Balance Sheet
A2: Month-end balance sheet (GBP)
A4: Period | B4: FY | C4: Trade AR | D4: Inventory | E4: Trade AP | F4: Net trade WC | G4: Cash | H4: Net fixed assets | I4: Other current assets | J4: Total assets | K4: Other liabilities | L4: Tax payable | M4: Borrowings | N4: Share capital | O4: Retained earnings | P4: Liabilities + equity | Q4: Balance check | R4: Source ID | S4: Context ID
A5: 45688 | B5: 2025 | C5: 1390000 | D5: 1090000 | E5: 940000 | F5: =C5+D5-E5 -> 1540000 | G5: =P5-SUM(C5:D5)-H5-I5 -> 1598850 | H5: 2010000 | I5: 100000 | J5: =SUM(C5:D5)+SUM(G5:I5) -> 6188850 | K5: 150000 | L5: 80000 | M5: 2000000 | N5: 1000000 | O5: =2000000+'Management PL'!N5-20000 -> 2018850 | P5: =E5+SUM(K5:O5) -> 6188850 | Q5: =J5-P5 -> 0 | R5: BS-2025-01 | S5: CTX-BS
A6: 45716 | B6: 2025 | C6: 1400000 | D6: 1100000 | E6: 950000 | F6: =C6+D6-E6 -> 1550000 | G6: =P6-SUM(C6:D6)-H6-I6 -> 1605125 | H6: 2020000 | I6: 100000 | J6: =SUM(C6:D6)+SUM(G6:I6) -> 6225125 | K6: 150000 | L6: 80000 | M6: 2000000 | N6: 1000000 | O6: =O5+'Management PL'!N6-20000 -> 2045125 | P6: =E6+SUM(K6:O6) -> 6225125 | Q6: =J6-P6 -> 0 | R6: BS-2025-02 | S6: CTX-BS
A7: 45747 | B7: 2025 | C7: 1410000 | D7: 1110000 | E7: 960000 | F7: =C7+D7-E7 -> 1560000 | G7: =P7-SUM(C7:D7)-H7-I7 -> 1618825 | H7: 2030000 | I7: 100000 | J7: =SUM(C7:D7)+SUM(G7:I7) -> 6268825 | K7: 150000 | L7: 80000 | M7: 2000000 | N7: 1000000 | O7: =O6+'Management PL'!N7-20000 -> 2078825 | P7: =E7+SUM(K7:O7) -> 6268825 | Q7: =J7-P7 -> 0 | R7: BS-2025-03 | S7: CTX-BS
A8: 45777 | B8: 2025 | C8: 1420000 | D8: 1120000 | E8: 970000 | F8: =C8+D8-E8 -> 1570000 | G8: =P8-SUM(C8:D8)-H8-I8 -> 1626450 | H8: 2040000 | I8: 100000 | J8: =SUM(C8:D8)+SUM(G8:I8) -> 6306450 | K8: 150000 | L8: 80000 | M8: 2000000 | N8: 1000000 | O8: =O7+'Management PL'!N8-20000 -> 2106450 | P8: =E8+SUM(K8:O8) -> 6306450 | Q8: =J8-P8 -> 0 | R8: BS-2025-04 | S8: CTX-BS
A9: 45808 | B9: 2025 | C9: 1430000 | D9: 1130000 | E9: 980000 | F9: =C9+D9-E9 -> 1580000 | G9: =P9-SUM(C9:D9)-H9-I9 -> 1643600 | H9: 2050000 | I9: 100000 | J9: =SUM(C9:D9)+SUM(G9:I9) -> 6353600 | K9: 150000 | L9: 80000 | M9: 2000000 | N9: 1000000 | O9: =O8+'Management PL'!N9-20000 -> 2143600 | P9: =E9+SUM(K9:O9) -> 6353600 | Q9: =J9-P9 -> 0 | R9: BS-2025-05 | S9: CTX-BS
A10: 45838 | B10: 2025 | C10: 1440000 | D10: 1140000 | E10: 990000 | F10: =C10+D10-E10 -> 1590000 | G10: =P10-SUM(C10:D10)-H10-I10 -> 1665400 | H10: 2060000 | I10: 100000 | J10: =SUM(C10:D10)+SUM(G10:I10) -> 6405400 | K10: 150000 | L10: 80000 | M10: 2000000 | N10: 1000000 | O10: =O9+'Management PL'!N10-20000 -> 2185400 | P10: =E10+SUM(K10:O10) -> 6405400 | Q10: =J10-P10 -> 0 | R10: BS-2025-06 | S10: CTX-BS
A11: 45869 | B11: 2025 | C11: 1450000 | D11: 1150000 | E11: 1000000 | F11: =C11+D11-E11 -> 1600000 | G11: =P11-SUM(C11:D11)-H11-I11 -> 1672275 | H11: 2070000 | I11: 100000 | J11: =SUM(C11:D11)+SUM(G11:I11) -> 6442275 | K11: 150000 | L11: 80000 | M11: 2000000 | N11: 1000000 | O11: =O10+'Management PL'!N11-20000 -> 2212275 | P11: =E11+SUM(K11:O11) -> 6442275 | Q11: =J11-P11 -> 0 | R11: BS-2025-07 | S11: CTX-BS
A12: 45900 | B12: 2025 | C12: 1460000 | D12: 1160000 | E12: 1010000 | F12: =C12+D12-E12 -> 1610000 | G12: =P12-SUM(C12:D12)-H12-I12 -> 1667750 | H12: 2080000 | I12: 100000 | J12: =SUM(C12:D12)+SUM(G12:I12) -> 6467750 | K12: 150000 | L12: 80000 | M12: 2000000 | N12: 1000000 | O12: =O11+'Management PL'!N12-20000 -> 2227750 | P12: =E12+SUM(K12:O12) -> 6467750 | Q12: =J12-P12 -> 0 | R12: BS-2025-08 | S12: CTX-BS
A13: 45930 | B13: 2025 | C13: 1470000 | D13: 1170000 | E13: 1020000 | F13: =C13+D13-E13 -> 1620000 | G13: =P13-SUM(C13:D13)-H13-I13 -> 1686100 | H13: 2090000 | I13: 100000 | J13: =SUM(C13:D13)+SUM(G13:I13) -> 6516100 | K13: 150000 | L13: 80000 | M13: 2000000 | N13: 1000000 | O13: =O12+'Management PL'!N13-20000 -> 2266100 | P13: =E13+SUM(K13:O13) -> 6516100 | Q13: =J13-P13 -> 0 | R13: BS-2025-09 | S13: CTX-BS
A14: 45961 | B14: 2025 | C14: 1480000 | D14: 1180000 | E14: 1030000 | F14: =C14+D14-E14 -> 1630000 | G14: =P14-SUM(C14:D14)-H14-I14 -> 1719525 | H14: 2100000 | I14: 100000 | J14: =SUM(C14:D14)+SUM(G14:I14) -> 6579525 | K14: 150000 | L14: 80000 | M14: 2000000 | N14: 1000000 | O14: =O13+'Management PL'!N14-20000 -> 2319525 | P14: =E14+SUM(K14:O14) -> 6579525 | Q14: =J14-P14 -> 0 | R14: BS-2025-10 | S14: CTX-BS
A15: 45991 | B15: 2025 | C15: 1490000 | D15: 1190000 | E15: 1040000 | F15: =C15+D15-E15 -> 1640000 | G15: =P15-SUM(C15:D15)-H15-I15 -> 1764575 | H15: 2110000 | I15: 100000 | J15: =SUM(C15:D15)+SUM(G15:I15) -> 6654575 | K15: 150000 | L15: 80000 | M15: 2000000 | N15: 1000000 | O15: =O14+'Management PL'!N15-20000 -> 2384575 | P15: =E15+SUM(K15:O15) -> 6654575 | Q15: =J15-P15 -> 0 | R15: BS-2025-11 | S15: CTX-BS
A16: 46022 | B16: 2025 | C16: 1500000 | D16: 1200000 | E16: 1050000 | F16: =C16+D16-E16 -> 1650000 | G16: =P16-SUM(C16:D16)-H16-I16 -> 1840000 | H16: 2120000 | I16: 100000 | J16: =SUM(C16:D16)+SUM(G16:I16) -> 6760000 | K16: 150000 | L16: 80000 | M16: 2000000 | N16: 1000000 | O16: =O15+'Management PL'!N16-20000 -> 2480000 | P16: =E16+SUM(K16:O16) -> 6760000 | Q16: =J16-P16 -> 0 | R16: BS-2025-12 | S16: CTX-BS
A17: 46053 | B17: 2026 | C17: 1536667 | D17: 1223333 | E17: 1063333 | F17: =C17+D17-E17 -> 1696667 | G17: =P17-SUM(C17:D17)-H17-I17 -> 1793333 | H17: 2130000 | I17: 100000 | J17: =SUM(C17:D17)+SUM(G17:I17) -> 6783333 | K17: 150000 | L17: 80000 | M17: 2000000 | N17: 1000000 | O17: =O16+'Management PL'!N17-20000 -> 2490000 | P17: =E17+SUM(K17:O17) -> 6783333 | Q17: =J17-P17 -> 0 | R17: BS-2026-01 | S17: CTX-BS
... A28: 46387 | B28: 2026 | C28: 2050000 | D28: 1550000 | E28: 1250000 | F28: =C28+D28-E28 -> 2350000 | G28: =P28-SUM(C28:D28)-H28-I28 -> 1386375 | H28: 2240000 | I28: 100000 | J28: =SUM(C28:D28)+SUM(G28:I28) -> 7326375 | K28: 150000 | L28: 80000 | M28: 2000000 | N28: 1000000 | O28: =O27+'Management PL'!N28-20000 -> 2846375 | P28: =E28+SUM(K28:O28) -> 7326375 | Q28: =J28-P28 -> 0 | R28: BS-2026-12 | S28: CTX-BS

Sheet Customer Product
A2: Customer / product monthly detail (GBP)
A4: Period | B4: FY | C4: Customer ID | D4: Product | E4: Revenue | F4: Units sold | G4: Unit price GBP | H4: Contribution 0 | I4: Lifecycle | J4: Source ID | K4: Context ID
A5: 45658 | B5: 2025 | C5: CUST-01 | D5: Product A | E5: 416600 | F5: =E5/G5 -> 4166 | G5: 100 | H5: =E5*0.4 -> 166640 | I5: RETAINED | J5: CP-2025-01 | K5: CTX-DETAIL
A6: 45658 | B6: 2025 | C6: CUST-02 | D6: Product B | E6: 333320 | F6: =E6/G6 -> 8333 | G6: 40 | H6: =E6*0.22 -> 73330.4 | I6: RETAINED | J6: CP-2025-01 | K6: CTX-DETAIL
A7: 45658 | B7: 2025 | C7: CUST-03 | D7: Other assemblies | E7: 50000 | H7: =E7*0.25 -> 12500 | I7: RETAINED | J7: CP-2025-01 | K7: CTX-DETAIL
A8: 45658 | B8: 2025 | C8: CUST-04 | D8: New product | E8: 0 | H8: =E8*0.25 -> 0 | I8: NEW | J8: CP-2025-01 | K8: CTX-DETAIL
A9: 45658 | B9: 2025 | C9: CUST-05 | D9: Lost product | E9: 12500 | H9: =E9*0.25 -> 3125 | I9: LOST | J9: CP-2025-01 | K9: CTX-DETAIL
A10: 45689 | B10: 2025 | C10: CUST-01 | D10: Product A | E10: 416600 | F10: =E10/G10 -> 4166 | G10: 100 | H10: =E10*0.4 -> 166640 | I10: RETAINED | J10: CP-2025-02 | K10: CTX-DETAIL
A11: 45689 | B11: 2025 | C11: CUST-02 | D11: Product B | E11: 333320 | F11: =E11/G11 -> 8333 | G11: 40 | H11: =E11*0.22 -> 73330.4 | I11: RETAINED | J11: CP-2025-02 | K11: CTX-DETAIL
A12: 45689 | B12: 2025 | C12: CUST-03 | D12: Other assemblies | E12: 50000 | H12: =E12*0.25 -> 12500 | I12: RETAINED | J12: CP-2025-02 | K12: CTX-DETAIL
A13: 45689 | B13: 2025 | C13: CUST-04 | D13: New product | E13: 0 | H13: =E13*0.25 -> 0 | I13: NEW | J13: CP-2025-02 | K13: CTX-DETAIL
A14: 45689 | B14: 2025 | C14: CUST-05 | D14: Lost product | E14: 12500 | H14: =E14*0.25 -> 3125 | I14: LOST | J14: CP-2025-02 | K14: CTX-DETAIL
A15: 45717 | B15: 2025 | C15: CUST-01 | D15: Product A | E15: 416600 | F15: =E15/G15 -> 4166 | G15: 100 | H15: =E15*0.4 -> 166640 | I15: RETAINED | J15: CP-2025-03 | K15: CTX-DETAIL
A16: 45717 | B16: 2025 | C16: CUST-02 | D16: Product B | E16: 333320 | F16: =E16/G16 -> 8333 | G16: 40 | H16: =E16*0.22 -> 73330.4 | I16: RETAINED | J16: CP-2025-03 | K16: CTX-DETAIL
A17: 45717 | B17: 2025 | C17: CUST-03 | D17: Other assemblies | E17: 50000 | H17: =E17*0.25 -> 12500 | I17: RETAINED | J17: CP-2025-03 | K17: CTX-DETAIL
A18: 45717 | B18: 2025 | C18: CUST-04 | D18: New product | E18: 0 | H18: =E18*0.25 -> 0 | I18: NEW | J18: CP-2025-03 | K18: CTX-DETAIL
A19: 45717 | B19: 2025 | C19: CUST-05 | D19: Lost product | E19: 12500 | H19: =E19*0.25 -> 3125 | I19: LOST | J19: CP-2025-03 | K19: CTX-DETAIL
A20: 45748 | B20: 2025 | C20: CUST-01 | D20: Product A | E20: 416600 | F20: =E20/G20 -> 4166 | G20: 100 | H20: =E20*0.4 -> 166640 | I20: RETAINED | J20: CP-2025-04 | K20: CTX-DETAIL
A21: 45748 | B21: 2025 | C21: CUST-02 | D21: Product B | E21: 333320 | F21: =E21/G21 -> 8333 | G21: 40 | H21: =E21*0.22 -> 73330.4 | I21: RETAINED | J21: CP-2025-04 | K21: CTX-DETAIL
A22: 45748 | B22: 2025 | C22: CUST-03 | D22: Other assemblies | E22: 50000 | H22: =E22*0.25 -> 12500 | I22: RETAINED | J22: CP-2025-04 | K22: CTX-DETAIL
A23: 45748 | B23: 2025 | C23: CUST-04 | D23: New product | E23: 0 | H23: =E23*0.25 -> 0 | I23: NEW | J23: CP-2025-04 | K23: CTX-DETAIL
A24: 45748 | B24: 2025 | C24: CUST-05 | D24: Lost product | E24: 12500 | H24: =E24*0.25 -> 3125 | I24: LOST | J24: CP-2025-04 | K24: CTX-DETAIL
A25: 45778 | B25: 2025 | C25: CUST-01 | D25: Product A | E25: 416600 | F25: =E25/G25 -> 4166 | G25: 100 | H25: =E25*0.4 -> 166640 | I25: RETAINED | J25: CP-2025-05 | K25: CTX-DETAIL
A26: 45778 | B26: 2025 | C26: CUST-02 | D26: Product B | E26: 333320 | F26: =E26/G26 -> 8333 | G26: 40 | H26: =E26*0.22 -> 73330.4 | I26: RETAINED | J26: CP-2025-05 | K26: CTX-DETAIL
A27: 45778 | B27: 2025 | C27: CUST-03 | D27: Other assemblies | E27: 50000 | H27: =E27*0.25 -> 12500 | I27: RETAINED | J27: CP-2025-05 | K27: CTX-DETAIL
A28: 45778 | B28: 2025 | C28: CUST-04 | D28: New product | E28: 0 | H28: =E28*0.25 -> 0 | I28: NEW | J28: CP-2025-05 | K28: CTX-DETAIL
A29: 45778 | B29: 2025 | C29: CUST-05 | D29: Lost product | E29: 12500 | H29: =E29*0.25 -> 3125 | I29: LOST | J29: CP-2025-05 | K29: CTX-DETAIL
A30: 45809 | B30: 2025 | C30: CUST-01 | D30: Product A | E30: 416600 | F30: =E30/G30 -> 4166 | G30: 100 | H30: =E30*0.4 -> 166640 | I30: RETAINED | J30: CP-2025-06 | K30: CTX-DETAIL
A31: 45809 | B31: 2025 | C31: CUST-02 | D31: Product B | E31: 333320 | F31: =E31/G31 -> 8333 | G31: 40 | H31: =E31*0.22 -> 73330.4 | I31: RETAINED | J31: CP-2025-06 | K31: CTX-DETAIL
A32: 45809 | B32: 2025 | C32: CUST-03 | D32: Other assemblies | E32: 50000 | H32: =E32*0.25 -> 12500 | I32: RETAINED | J32: CP-2025-06 | K32: CTX-DETAIL
A33: 45809 | B33: 2025 | C33: CUST-04 | D33: New product | E33: 0 | H33: =E33*0.25 -> 0 | I33: NEW | J33: CP-2025-06 | K33: CTX-DETAIL
A34: 45809 | B34: 2025 | C34: CUST-05 | D34: Lost product | E34: 12500 | H34: =E34*0.25 -> 3125 | I34: LOST | J34: CP-2025-06 | K34: CTX-DETAIL
A35: 45839 | B35: 2025 | C35: CUST-01 | D35: Product A | E35: 416600 | F35: =E35/G35 -> 4166 | G35: 100 | H35: =E35*0.4 -> 166640 | I35: RETAINED | J35: CP-2025-07 | K35: CTX-DETAIL
A36: 45839 | B36: 2025 | C36: CUST-02 | D36: Product B | E36: 333320 | F36: =E36/G36 -> 8333 | G36: 40 | H36: =E36*0.22 -> 73330.4 | I36: RETAINED | J36: CP-2025-07 | K36: CTX-DETAIL
A37: 45839 | B37: 2025 | C37: CUST-03 | D37: Other assemblies | E37: 50000 | H37: =E37*0.25 -> 12500 | I37: RETAINED | J37: CP-2025-07 | K37: CTX-DETAIL
A38: 45839 | B38: 2025 | C38: CUST-04 | D38: New product | E38: 0 | H38: =E38*0.25 -> 0 | I38: NEW | J38: CP-2025-07 | K38: CTX-DETAIL
A39: 45839 | B39: 2025 | C39: CUST-05 | D39: Lost product | E39: 12500 | H39: =E39*0.25 -> 3125 | I39: LOST | J39: CP-2025-07 | K39: CTX-DETAIL
A40: 45870 | B40: 2025 | C40: CUST-01 | D40: Product A | E40: 416600 | F40: =E40/G40 -> 4166 | G40: 100 | H40: =E40*0.4 -> 166640 | I40: RETAINED | J40: CP-2025-08 | K40: CTX-DETAIL
A41: 45870 | B41: 2025 | C41: CUST-02 | D41: Product B | E41: 333320 | F41: =E41/G41 -> 8333 | G41: 40 | H41: =E41*0.22 -> 73330.4 | I41: RETAINED | J41: CP-2025-08 | K41: CTX-DETAIL
A42: 45870 | B42: 2025 | C42: CUST-03 | D42: Other assemblies | E42: 50000 | H42: =E42*0.25 -> 12500 | I42: RETAINED | J42: CP-2025-08 | K42: CTX-DETAIL
...

Sheet Versions
A2: Revenue source versions (GBP)
A4: Record ID | B4: Period | C4: Metric | D4: Version | E4: Amount | F4: Status | G4: Superseded by | H4: Release date | I4: Context ID | J4: Reason
A5: MA-2025-01-REV-v1 | B5: 45658 | C5: Revenue | D5: 1 | E5: 900000 | F5: CANONICAL | H5: 45698 | I5: CTX-PL | J5: Original monthly release.
A6: MA-2025-02-REV-v1 | B6: 45689 | C6: Revenue | D6: 1 | E6: 936000 | F6: CANONICAL | H6: 45726 | I6: CTX-PL | J6: Original monthly release.
A7: MA-2025-03-REV-v1 | B7: 45717 | C7: Revenue | D7: 1 | E7: 972000 | F7: CANONICAL | H7: 45757 | I7: CTX-PL | J7: Original monthly release.
A8: MA-2025-04-REV-v1 | B8: 45748 | C8: Revenue | D8: 1 | E8: 948000 | F8: CANONICAL | H8: 45787 | I8: CTX-PL | J8: Original monthly release.
A9: MA-2025-05-REV-v1 | B9: 45778 | C9: Revenue | D9: 1 | E9: 984000 | F9: CANONICAL | H9: 45818 | I9: CTX-PL | J9: Original monthly release.
A10: MA-2025-06-REV-v1 | B10: 45809 | C10: Revenue | D10: 1 | E10: 1008000 | F10: CANONICAL | H10: 45848 | I10: CTX-PL | J10: Original monthly release.
A11: MA-2025-07-REV-v1 | B11: 45839 | C11: Revenue | D11: 1 | E11: 948000 | F11: CANONICAL | H11: 45879 | I11: CTX-PL | J11: Original monthly release.
A12: MA-2025-08-REV-v1 | B12: 45870 | C12: Revenue | D12: 1 | E12: 900000 | F12: CANONICAL | H12: 45910 | I12: CTX-PL | J12: Original monthly release.
A13: MA-2025-09-REV-v1 | B13: 45901 | C13: Revenue | D13: 1 | E13: 996000 | F13: CANONICAL | H13: 45940 | I13: CTX-PL | J13: Original monthly release.
A14: MA-2025-10-REV-v1 | B14: 45931 | C14: Revenue | D14: 1 | E14: 1056000 | F14: CANONICAL | H14: 45971 | I14: CTX-PL | J14: Original monthly release.
A15: MA-2025-11-REV-v1 | B15: 45962 | C15: Revenue | D15: 1 | E15: 1104000 | F15: CANONICAL | H15: 46001 | I15: CTX-PL | J15: Original monthly release.
A16: MA-2025-12-REV-v1 | B16: 45992 | C16: Revenue | D16: 1 | E16: 1248000 | F16: CANONICAL | H16: 46032 | I16: CTX-PL | J16: Original monthly release.
... A18: MA-2026-02-REV-v1 | B18: 46054 | C18: Revenue | D18: 1 | E18: 1040000 | F18: CANONICAL | H18: 46091 | I18: CTX-PL | J18: Original monthly release.
A19: MA-2026-03-REV-v1 | B19: 46082 | C19: Revenue | D19: 1 | E19: 1117000 | F19: SUPERSEDED | G19: MA-2026-03-REV-v2 | H19: 46152 | I19: CTX-PL | J19: 50,000 revenue belongs to April, originally recognised in March.
A20: MA-2026-03-REV-v2 | B20: 46082 | C20: Revenue | D20: 2 | E20: 1067000 | F20: CANONICAL | H20: 46162 | I20: CTX-PL | J20: Paired March/April restatement. Use both v2 records.
A21: MA-2026-04-REV-v1 | B21: 46113 | C21: Revenue | D21: 1 | E21: 1003000 | F21: SUPERSEDED | G21: MA-2026-04-REV-v2 | H21: 46152 | I21: CTX-PL | J21: 50,000 revenue belongs to April, originally recognised in March.
A22: MA-2026-04-REV-v2 | B22: 46113 | C22: Revenue | D22: 2 | E22: 1053000 | F22: CANONICAL | H22: 46162 | I22: CTX-PL | J22: Paired March/April restatement. Use both v2 records.
A23: MA-2026-05-REV-v1 | B23: 46143 | C23: Revenue | D23: 1 | E23: 1107000 | F23: CANONICAL | H23: 46183 | I23: CTX-PL | J23: Original monthly release.
A24: MA-2026-06-REV-v1 | B24: 46174 | C24: Revenue | D24: 1 | E24: 1148000 | F24: CANONICAL | H24: 46213 | I24: CTX-PL | J24: Original monthly release.
A25: MA-2026-07-REV-v1 | B25: 46204 | C25: Revenue | D25: 1 | E25: 1094000 | F25: CANONICAL | H25: 46244 | I25: CTX-PL | J25: Original monthly release.
A26: MA-2026-08-REV-v1 | B26: 46235 | C26: Revenue | D26: 1 | E26: 1040000 | F26: CANONICAL | H26: 46275 | I26: CTX-PL | J26: Original monthly release.
A27: MA-2026-09-REV-v1 | B27: 46266 | C27: Revenue | D27: 1 | E27: 1134000 | F27: CANONICAL | H27: 46305 | I27: CTX-PL | J27: Original monthly release.
A28: MA-2026-10-REV-v1 | B28: 46296 | C28: Revenue | D28: 1 | E28: 1215000 | F28: CANONICAL | H28: 46336 | I28: CTX-PL | J28: Original monthly release.
A29: MA-2026-11-REV-v1 | B29: 46327 | C29: Revenue | D29: 1 | E29: 1269000 | F29: CANONICAL | H29: 46366 | I29: CTX-PL | J29: Original monthly release.
A30: MA-2026-12-REV-v1 | B30: 46357 | C30: Revenue | D30: 1 | E30: 1347000 | F30: CANONICAL | H30: 46397 | I30: CTX-PL | J30: Original monthly release.

Sheet Cash and Output
A2: Cash indicators and incomplete output evidence
A4: Period | B4: Asset additions GBP | C4: Dividends GBP | D4: Cash-flow class | E4: Operating cash GBP | F4: Output units | G4: Output scope | H4: Source ID | I4: Context IDs
A5: 45658 | B5: 30000 | C5: 20000 | D5: UNCLASSIFIED | G5: No comparable output evidence | H5: CASH-2025-01 | I5: CTX-CASH / CTX-OUTPUT
A6: 45689 | B6: 30000 | C6: 20000 | D6: UNCLASSIFIED | G6: No comparable output evidence | H6: CASH-2025-02 | I6: CTX-CASH / CTX-OUTPUT
A7: 45717 | B7: 30000 | C7: 20000 | D7: UNCLASSIFIED | G7: No comparable output evidence | H7: CASH-2025-03 | I7: CTX-CASH / CTX-OUTPUT
A8: 45748 | B8: 30000 | C8: 20000 | D8: UNCLASSIFIED | G8: No comparable output evidence | H8: CASH-2025-04 | I8: CTX-CASH / CTX-OUTPUT
A9: 45778 | B9: 30000 | C9: 20000 | D9: UNCLASSIFIED | G9: No comparable output evidence | H9: CASH-2025-05 | I9: CTX-CASH / CTX-OUTPUT
A10: 45809 | B10: 30000 | C10: 20000 | D10: UNCLASSIFIED | G10: No comparable output evidence | H10: CASH-2025-06 | I10: CTX-CASH / CTX-OUTPUT
A11: 45839 | B11: 30000 | C11: 20000 | D11: UNCLASSIFIED | G11: No comparable output evidence | H11: CASH-2025-07 | I11: CTX-CASH / CTX-OUTPUT
A12: 45870 | B12: 30000 | C12: 20000 | D12: UNCLASSIFIED | G12: No comparable output evidence | H12: CASH-2025-08 | I12: CTX-CASH / CTX-OUTPUT
A13: 45901 | B13: 30000 | C13: 20000 | D13: UNCLASSIFIED | G13: No comparable output evidence | H13: CASH-2025-09 | I13: CTX-CASH / CTX-OUTPUT
A14: 45931 | B14: 30000 | C14: 20000 | D14: UNCLASSIFIED | G14: No comparable output evidence | H14: CASH-2025-10 | I14: CTX-CASH / CTX-OUTPUT
A15: 45962 | B15: 30000 | C15: 20000 | D15: UNCLASSIFIED | G15: No comparable output evidence | H15: CASH-2025-11 | I15: CTX-CASH / CTX-OUTPUT
A16: 45992 | B16: 30000 | C16: 20000 | D16: UNCLASSIFIED | G16: No comparable output evidence | H16: CASH-2025-12 | I16: CTX-CASH / CTX-OUTPUT
... A22: 46174 | B22: 30000 | C22: 20000 | D22: UNCLASSIFIED | G22: No comparable output evidence | H22: CASH-2026-06 | I22: CTX-CASH / CTX-OUTPUT
A23: 46204 | B23: 30000 | C23: 20000 | D23: UNCLASSIFIED | F23: 11000 | G23: Product B line good units completed | H23: CASH-2026-07 | I23: CTX-CASH / CTX-OUTPUT
A24: 46235 | B24: 30000 | C24: 20000 | D24: UNCLASSIFIED | F24: 11250 | G24: Product B line good units completed | H24: CASH-2026-08 | I24: CTX-CASH / CTX-OUTPUT
A25: 46266 | B25: 30000 | C25: 20000 | D25: UNCLASSIFIED | F25: 11500 | G25: Product B line good units completed | H25: CASH-2026-09 | I25: CTX-CASH / CTX-OUTPUT
A26: 46296 | B26: 30000 | C26: 20000 | D26: UNCLASSIFIED | F26: 11750 | G26: Product B line good units completed | H26: CASH-2026-10 | I26: CTX-CASH / CTX-OUTPUT
A27: 46327 | B27: 30000 | C27: 20000 | D27: UNCLASSIFIED | F27: 12000 | G27: Product B line good units completed | H27: CASH-2026-11 | I27: CTX-CASH / CTX-OUTPUT
A28: 46357 | B28: 30000 | C28: 20000 | D28: UNCLASSIFIED | F28: 12250 | G28: Product B line good units completed | H28: CASH-2026-12 | I28: CTX-CASH / CTX-OUTPUT

Sheet Context
A2: Measurement context and source registry
A4: Context ID | B4: Entity | C4: Currency / scale | D4: Measurement | E4: Period scope | F4: Population | G4: Basis / definition | H4: Source / version | I4: Availability notes
A5: CTX-PL | B5: Golden Manufacturing Ltd | C5: GBP / whole pounds | D5: Monthly flow | E5: Jan 2025 to Dec 2026 | F5: Complete legal entity | G5: Accrual management accounts. Contribution 0 equals revenue less costs before C0. Same accounting basis throughout. | H5: MA-YYYY-MM. v2 for Mar/Apr 2026. | I5: Canonical records; version history supplied separately.
A6: CTX-BS | B6: Golden Manufacturing Ltd | C6: GBP / whole pounds | D6: Month-end stock | E6: Jan 2025 to Dec 2026 | F6: Complete legal entity | G6: Consistent balance definitions. Net trade working capital equals trade receivables plus inventory less trade payables. | H6: BS-YYYY-MM / v1 | I6: Cash is a balance-sheet stock. Transaction cash-flow classifications are not supplied.
A7: CTX-DETAIL | B7: Golden Manufacturing Ltd | C7: GBP / whole pounds | D7: Monthly flow | E7: Jan 2025 to Dec 2026 | F7: Nonrandom selected customer/product population | G7: Revenue and Contribution 0 by customer/product. A/B units comparable within SKU. Other unit fields are blank. | H7: CP-YYYY-MM / v1, aligned to restated accounts | I7: The selected population is not the complete entity.
A8: CTX-CASH | B8: Golden Manufacturing Ltd | C8: GBP / whole pounds | D8: Monthly indicators | E8: Jan 2025 to Dec 2026 | F8: Partial cash classification | G8: Cash stock, asset additions and dividends. No cash-flow mapping or noncash reconciliation is supplied. | H8: CASH-YYYY-MM / v1 | I8: Payment timing, tax/interest payments and classified cash transactions are not supplied.
A9: CTX-OUTPUT | B9: Golden Manufacturing Ltd | C9: Physical units / count | D9: Monthly flow | E9: Only Jul to Dec 2026 | F9: Product B line only | G9: Good units completed, distinct from units sold. No FY2025 equivalent, other products, WIP or rejects reconciliation is supplied. | H9: OPS-YYYY-MM / v1 | I9: Payroll and overhead relate to the full legal entity.
A10: DESIGN-v1 | B10: Golden Manufacturing Ltd | C10: GBP / whole pounds | D10: Synthetic fixture design | E10: 24 calendar months, December year-end | F10: 32 employees, UK owner-managed manufacturer | G10: Synthetic management accounts, balance-sheet records and customer/product allocations. | H10: Dataset v2.48 / build 1 | I10: All records are synthetic. Release dates are scenario dates, including future months.
